Workbook

Sheet Inversión inicial
B2: AeroGuardia
B4: CÁLCULO DE LA INVERSIÓN INICIAL
B6: CONCEPTO | C6: CANTIDAD
B7: Desarrollo inicial del software | C7: 250000
B8: Auditoría y pruebas de ciberseguridad | C8: 80000
B9: Diseño de interfaz y experiencia de usuario (UI/UX) | C9: 30000
B10: Infraestructura tecnológica inicial | C10: 20000
B11: Registro de marca y asesoría legal | C11: 25000
B12: Desarrollo de sitio web corporativo | C12: 15000
B13: Equipo demostrativo de hardware | C13: 30000
B14: Fondo operativo inicial | C14: 50000
B15: Equipo de transporte y entrega | C15: 0
B16: Activos diferidos
B17: Depósito y renta | C17: 0
B18: Gastos de instalación (remodelaciones) | C18: 0
B19: Gastos de organización (notario, permisos, escrituras, honorarios, etc.) | C19: 0
B20: Gastos para iniciar operaciones (papelería, consumibles, artículos varios) | C20: 0
B21: Gastos de mercadotecnia | C21: 0
B22: Activos intangibles
B23: Patentes y marcas | C23: 0
B24: Dominios de internet | C24: 0
B25: Licencias de uso (software) | C25: 0
B26: TOTAL DE INVERSIÓN INICIAL | C26: =SUM(C7:C14)
B29: ESTRUCTURA FINANCIERA | D29: $(MXN)
B31: Patrimonio propio | C31: 0 | D31: =C26*C31
B32: Recursos ajenos (crédito) | C32: 1 | D32: =C26*C32

Sheet  Proyeccion de ventas en unidad
A2: AeroGuardia
A4: PRONÓSTICO DE NUEVAS IMPLEMENTACIONES (CLIENTES NUEVOS) — AÑO 1
A5: MES | B5: CLIENTES NUEVOS (IMPLEMENTACIONES)
A6: ENERO | B6: 0
A7: FEBRERO | B7: 1
A8: MARZO | B8: 0
A9: ABRIL | B9: 1
A10: MAYO | B10: 0
A11: JUNIO | B11: 1
A12: JULIO | B12: 0
A13: AGOSTO | B13: 1
A14: SEPTIEMBRE | B14: 0
A15: OCTUBRE | B15: 1
A16: NOVIEMBRE | B16: 0
A17: DICIEMBRE | B17: 0
A18: Totales | B18: =SUM(B6:B17)
A20: Clientes el primer año | B20: 5

Sheet Presupuesto de operación
A1: PRESUPUESTO DE OPERACIÓN
A3: AeroGuardia
A5: Precios de venta | B5: Primer semestre
A6: Cuota de implementación (por cliente nuevo) | B6: ='Costos y precio de venta'!B71
A8: Ventas presupuestadas en unidades el primer año (clientes nuevos)
A10: Concepto | B10: Primer año
A11: Implementaciones nuevas | B11: 5
A12: Total | B12: =SUM(B11:B11)
A14: 1.- Presupuesto de ventas por implementación
A16: Servicio | B16: Primer Año
A17: Cuota de implementación | B17: =B6*B12
A18: Total | B18: =SUM(B17:B17)
A20: Suscripción mensual | B20: Precio | C20: Costo variable
A21: Precio de suscripción / costo operativo por cliente | B21: ='Costos y precio de venta'!B74 | C21: ='Costos y precio de venta'!B73
A23: 2.-Presupuesto de gastos de venta anuales (100%, sin recorte)
A25: Concepto | B25: Cantidad
A26: Sueldo Director de Operaciones y Desarrollo Comercial | B26: ='Costos y precio de venta'!B10
A27: Publicidad y promoción digital | B27: ='Costos y precio de venta'!B11
A28: Total | B28: =SUM(B26:B27)
A30: 3.-Presupuesto de gastos de administración anuales (100%, sin recorte)
A32: Concepto | B32: Cantidad
A33: Sueldo Director General (CEO) y Director de Desarrollo | B33: ='Costos y precio de venta'!B27
A34: Hospedaje de la plataforma | B34: ='Costos y precio de venta'!B28
A35: Bases de datos y almacenamiento | B35: ='Costos y precio de venta'!B29
A36: Dominio, correo empresarial y certificados SSL | B36: ='Costos y precio de venta'!B30
A37: Licencias y herramientas de desarrollo | B37: ='Costos y precio de venta'!B31
A38: Servicios contables y administrativos | B38: ='Costos y precio de venta'!B32
A39: Internet y comunicaciones | B39: ='Costos y precio de venta'!B33
A40: Total | B40: =SUM(B33:B39)
A42: Nota: los años 1-2 aplican un recorte del 50% sobre los $50,000/mes de sueldos de
A43: fundadores (ver hoja 'Estado de Resultados'); esta hoja muestra los montos anuales al 100%.
A45: Pago mensual del crédito (Financieros, no es gasto de operación — ver Estado de Resultados) | B45: =Amortización!B10*12

Sheet Costos y precio de venta
A1: DETERMINACIÓN DEL PRECIO DE VENTA — AeroGuardia
A3: Sueldos de fundadores (Director General $30,000 + Director de Operaciones $20,000 = $50,000/mes) recortados 50% en años 1-2 mientras el negocio gana tracción
A7: 2.-Presupuesto de gastos de venta
A9: Concepto | B9: Cantidad
A10: Director de Operaciones y Desarrollo Comercial (sueldo anual, 100%) | B10: 240000
A11: Publicidad y promoción digital | B11: 60000
A12: Seguro social | B12: 7000
A13: Agua | B13: 500
A14: Luz | B14: 1000
A15: Teléfono | B15: 240
A16: Renta | B16: 1500
A17: Internet | B17: 150
A18: Mantenimiento de equipo de entrega | B18: 500
A19: Depreciaciones | B19: 500
A20: Publicidad y promoción | B20: 3000
A21: Gasolina | B21: 5000
A22: Total | B22: =SUM(B10:B11)
A24: 3.- Gastos de administración
A26: Concepto | B26: Cantidad
A27: Director General (CEO) y Director de Desarrollo (sueldo anual, 100%) | B27: 360000
A28: Hospedaje de la plataforma (cloud hosting) | B28: 30000
A29: Bases de datos y almacenamiento | B29: 18000
A30: Dominio, correo empresarial y certificados SSL | B30: 6000
A31: Licencias y herramientas de desarrollo | B31: 18000
A32: Servicios contables y administrativos | B32: 36000
A33: Internet y comunicaciones | B33: 12000
A34: Papelería y útiles de oficina | B34: 350
A35: Depreciaciones | B35: 500
A36: Total | B36: =SUM(B27:B33)
A38: Total costos fijos anuales (100%, sin recorte) | B38: =B22+B36
A40: Sueldos de fundadores (subtotal, 100%) | B40: 600000
A41: Otros costos fijos (no se recortan) | B41: =B38-B40
A43: Insumos directos x servicio (hardware e instalación, Tabla 18) | B43: 12450
A44: Sueldos directos x servicio (servicios de implementación, Tabla 19) | B44: 5750
A45: Costo variable unitario (costo real de implementación) | B45: =SUM(B43:B44)
A48: Determinación del precio
A50: Datos:
A51: Costos fijos | B51: =B38
A52: Costo variable unitario | B52: =B45
A53: Ventas esperadas (implementaciones) por mes | B53: ='Presupuesto de operación'!#REF!
...

Sheet Ventas presupuestadas en $
B1: VENTAS PRESUPUESTADAS AÑO 1 EN $ — AeroGuardia
B3: Concepto | C3: Enero | D3: Febrero | E3: Marzo | F3: Abril | G3: Mayo | H3: Junio | I3: Julio | J3: Agosto | K3: Septiembre | L3: Octubre | M3: Noviembre | N3: Diciembre | O3: Total
B4: Clientes nuevos (implementaciones) | C4: =' Proyeccion de ventas en unidad'!B6 | D4: =' Proyeccion de ventas en unidad'!B7 | E4: =' Proyeccion de ventas en unidad'!B8 | F4: =' Proyeccion de ventas en unidad'!B9 | G4: =' Proyeccion de ventas en unidad'!B10 | H4: =' Proyeccion de ventas en unidad'!B11 | I4: =' Proyeccion de ventas en unidad'!B12 | J4: =' Proyeccion de ventas en unidad'!B13 | K4: =' Proyeccion de ventas en unidad'!B14 | L4: =' Proyeccion de ventas en unidad'!B15 | M4: =' Proyeccion de ventas en unidad'!B16 | N4: =' Proyeccion de ventas en unidad'!B17 | O4: =SUM(C4:N4)
B5: Clientes activos (acumulado) | C5: =C4 | D5: =C5+D4 | E5: =D5+E4 | F5: =E5+F4 | G5: =F5+G4 | H5: =G5+H4 | I5: =H5+I4 | J5: =I5+J4 | K5: =J5+K4 | ... N5: =M5+N4
B6: Precio de implementación | C6: ='Costos y precio de venta'!$B$71 | D6: ='Costos y precio de venta'!$B$71 | E6: ='Costos y precio de venta'!$B$71 | F6: ='Costos y precio de venta'!$B$71 | G6: ='Costos y precio de venta'!$B$71 | H6: ='Costos y precio de venta'!$B$71 | I6: ='Costos y precio de venta'!$B$71 | J6: ='Costos y precio de venta'!$B$71 | ... N6: ='Costos y precio de venta'!$B$71 | O6: =SUM(C6:N6)
B7: Ingreso por implementación | C7: =C4*C6 | D7: =D4*D6 | E7: =E4*E6 | F7: =F4*F6 | G7: =G4*G6 | H7: =H4*H6 | I7: =I4*I6 | J7: =J4*J6 | ... N7: =N4*N6 | O7: =SUM(C7:N7)
B8: Precio de suscripción mensual | C8: ='Costos y precio de venta'!$B$74 | D8: ='Costos y precio de venta'!$B$74 | E8: ='Costos y precio de venta'!$B$74 | F8: ='Costos y precio de venta'!$B$74 | G8: ='Costos y precio de venta'!$B$74 | H8: ='Costos y precio de venta'!$B$74 | I8: ='Costos y precio de venta'!$B$74 | J8: ='Costos y precio de venta'!$B$74 | ... N8: ='Costos y precio de venta'!$B$74
B9: Ingreso por suscripción | C9: =C5*C8 | D9: =D5*D8 | E9: =E5*E8 | F9: =F5*F8 | G9: =G5*G8 | H9: =H5*H8 | I9: =I5*I8 | J9: =J5*J8 | ... N9: =N5*N8 | O9: =SUM(C9:N9)
B10: Total ventas | C10: =C7+C9 | D10: =D7+D9 | E10: =E7+E9 | F10: =F7+F9 | G10: =G7+G9 | H10: =H7+H9 | I10: =I7+I9 | J10: =J7+J9 | ... N10: =N7+N9 | O10: =SUM(C10:N10)
B12: Costo variable de implementación | C12: ='Costos y precio de venta'!$B$45 | D12: ='Costos y precio de venta'!$B$45 | E12: ='Costos y precio de venta'!$B$45 | F12: ='Costos y precio de venta'!$B$45 | G12: ='Costos y precio de venta'!$B$45 | H12: ='Costos y precio de venta'!$B$45 | I12: ='Costos y precio de venta'!$B$45 | J12: ='Costos y precio de venta'!$B$45 | ... N12: ='Costos y precio de venta'!$B$45
B13: Costo de implementación (COGS) | C13: =C4*C12 | D13: =D4*D12 | E13: =E4*E12 | F13: =F4*F12 | G13: =G4*G12 | H13: =H4*H12 | I13: =I4*I12 | J13: =J4*J12 | ... N13: =N4*N12 | O13: =SUM(C13:N13)
B14: Costo operativo mensual por cliente activo | C14: ='Costos y precio de venta'!$B$73 | D14: ='Costos y precio de venta'!$B$73 | E14: ='Costos y precio de venta'!$B$73 | F14: ='Costos y precio de venta'!$B$73 | G14: ='Costos y precio de venta'!$B$73 | H14: ='Costos y precio de venta'!$B$73 | I14: ='Costos y precio de venta'!$B$73 | J14: ='Costos y precio de venta'!$B$73 | ... N14: ='Costos y precio de venta'!$B$73
B15: Costo operativo de clientes activos | C15: =C5*C14 | D15: =D5*D14 | E15: =E5*E14 | F15: =F5*F14 | G15: =G5*G14 | H15: =H5*H14 | I15: =I5*I14 | J15: =J5*J14 | ... N15: =N5*N14 | O15: =SUM(C15:N15)
B16: Costo de ventas total | C16: =C13+C15 | D16: =D13+D15 | E16: =E13+E15 | F16: =F13+F15 | G16: =G13+G15 | H16: =H13+H15 | I16: =I13+I15 | J16: =J13+J15 | ... N16: =N13+N15 | O16: =SUM(C16:N16)

Sheet Estado de Resultados
A2: AeroGuardia
A4: ESTADO DE RESULTADOS PRESUPUESTADO | B4: AÑO 1 | O4: PROYECCIÓN POR CRECIMIENTO DE CARTERA DE CLIENTES (Tabla 26 del reporte, años 2-5) | P4: INCREMENTO DE VENTAS DEL 10% | Q4: INCREMENTO DE VENTAS DEL 15% | R4: INCREMENTO DE VENTAS DEL 25% | S4: AÑOS 6-8: EXTRAPOLACIÓN (no está en el reporte — ver nota) | V4: TOTAL 8 AÑOS | Y4: Supuestos años 2-8
B5: Enero | C5: Febrero | D5: Marzo | E5: Abril | F5: Mayo | G5: Junio | H5: Julio | I5: Agosto | J5: Septiembre | K5: Octubre | L5: Noviembre | M5: Diciembre | N5: Total año 1 | O5: AÑO 2 | P5: AÑO 3 | Q5: AÑO 4 | R5: AÑO 5 | S5: AÑO 6 | T5: AÑO 7 | U5: AÑO 8 | Y5: Año | Z5: Clientes inicio | AA5: Clientes fin | AB5: Clientes nuevos
A6: Ventas | B6: ='Ventas presupuestadas en $'!C10 | C6: ='Ventas presupuestadas en $'!D10 | D6: ='Ventas presupuestadas en $'!E10 | E6: ='Ventas presupuestadas en $'!F10 | F6: ='Ventas presupuestadas en $'!G10 | G6: ='Ventas presupuestadas en $'!H10 | H6: ='Ventas presupuestadas en $'!I10 | I6: ='Ventas presupuestadas en $'!J10 | ... M6: ='Ventas presupuestadas en $'!N10 | N6: =SUM(B6:M6) | O6: =((Z6+AA6)/2)*'Costos y precio de venta'!$B$74*12+AB6*'Costos y precio de venta'!$B$71 | P6: =((Z7+AA7)/2)*'Costos y precio de venta'!$B$74*12+AB7*'Costos y precio de venta'!$B$71 | Q6: =((Z8+AA8)/2)*'Costos y precio de venta'!$B$74*12+AB8*'Costos y precio de venta'!$B$71 | R6: =((Z9+AA9)/2)*'Costos y precio de venta'!$B$74*12+AB9*'Costos y precio de venta'!$B$71 | S6: =((Z10+AA10)/2)*'Costos y precio de venta'!$B$74*12+AB10*'Costos y precio de venta'!$B$71 | T6: =((Z11+AA11)/2)*'Costos y precio de venta'!$B$74*12+AB11*'Costos y precio de venta'!$B$71 | U6: =((Z12+AA12)/2)*'Costos y precio de venta'!$B$74*12+AB12*'Costos y precio de venta'!$B$71 | V6: =SUM(N6:U6) | Y6: 2 | Z6: 5 | AA6: 12 | AB6: 7
A7: Costo de Ventas | B7: ='Ventas presupuestadas en $'!C16 | C7: ='Ventas presupuestadas en $'!D16 | D7: ='Ventas presupuestadas en $'!E16 | E7: ='Ventas presupuestadas en $'!F16 | F7: ='Ventas presupuestadas en $'!G16 | G7: ='Ventas presupuestadas en $'!H16 | H7: ='Ventas presupuestadas en $'!I16 | I7: ='Ventas presupuestadas en $'!J16 | ... M7: ='Ventas presupuestadas en $'!N16 | N7: =SUM(B7:M7) | O7: =((Z6+AA6)/2)*'Costos y precio de venta'!$B$73*12+AB6*'Costos y precio de venta'!$B$45 | P7: =((Z7+AA7)/2)*'Costos y precio de venta'!$B$73*12+AB7*'Costos y precio de venta'!$B$45 | Q7: =((Z8+AA8)/2)*'Costos y precio de venta'!$B$73*12+AB8*'Costos y precio de venta'!$B$45 | R7: =((Z9+AA9)/2)*'Costos y precio de venta'!$B$73*12+AB9*'Costos y precio de venta'!$B$45 | S7: =((Z10+AA10)/2)*'Costos y precio de venta'!$B$73*12+AB10*'Costos y precio de venta'!$B$45 | T7: =((Z11+AA11)/2)*'Costos y precio de venta'!$B$73*12+AB11*'Costos y precio de venta'!$B$45 | U7: =((Z12+AA12)/2)*'Costos y precio de venta'!$B$73*12+AB12*'Costos y precio de venta'!$B$45 | V7: =SUM(N7:U7) | Y7: 3 | Z7: 12 | AA7: 20 | AB7: 8
A8: Utilidad Bruta | B8: =B6-B7 | C8: =C6-C7 | D8: =D6-D7 | E8: =E6-E7 | F8: =F6-F7 | G8: =G6-G7 | H8: =H6-H7 | I8: =I6-I7 | ... V8: =V6-V7 | Y8: 4 | Z8: 20 | AA8: 30 | AB8: 10
A9: Gastos de operación | Y9: 5 | Z9: 30 | AA9: 45 | AB9: 15
A10: Sueldos de fundadores (con recorte años 1-2) | B10: =($Z$16/12)*$Z$21 | C10: =($Z$16/12)*$Z$21 | D10: =($Z$16/12)*$Z$21 | E10: =($Z$16/12)*$Z$21 | F10: =($Z$16/12)*$Z$21 | G10: =($Z$16/12)*$Z$21 | H10: =($Z$16/12)*$Z$21 | I10: =($Z$16/12)*$Z$21 | ... M10: =($Z$16/12)*$Z$21 | N10: =SUM(B10:M10) | O10: =$Z$16*(1+$Z$14)^1*$Z$22 | P10: =$Z$16*(1+$Z$14)^2*$Z$23 | Q10: =$Z$16*(1+$Z$14)^3*$Z$24 | R10: =$Z$16*(1+$Z$14)^4*$Z$25 | S10: =$Z$16*(1+$Z$14)^5*$Z$26 | T10: =$Z$16*(1+$Z$14)^6*$Z$27 | U10: =$Z$16*(1+$Z$14)^7*$Z$28 | V10: =SUM(N10:U10) | Y10: 6 | Z10: 45 | AA10: 68 | AB10: 23
A11: Otros gastos fijos (venta + administración, sin recorte) | B11: =$Z$17/12 | C11: =$Z$17/12 | D11: =$Z$17/12 | E11: =$Z$17/12 | F11: =$Z$17/12 | G11: =$Z$17/12 | H11: =$Z$17/12 | I11: =$Z$17/12 | ... M11: =$Z$17/12 | N11: =SUM(B11:M11) | O11: =$Z$17*(1+$Z$14)^1 | P11: =$Z$17*(1+$Z$14)^2 | Q11: =$Z$17*(1+$Z$14)^3 | R11: =$Z$17*(1+$Z$14)^4 | S11: =$Z$17*(1+$Z$14)^5 | T11: =$Z$17*(1+$Z$14)^6 | U11: =$Z$17*(1+$Z$14)^7 | V11: =SUM(N11:U11) | Y11: 7 | Z11: 68 | AA11: 102 | AB11: 34
A12: Total gastos de operación | B12: =SUM(B10:B11) | C12: =SUM(C10:C11) | D12: =SUM(D10:D11) | E12: =SUM(E10:E11) | F12: =SUM(F10:F11) | G12: =SUM(G10:G11) | H12: =SUM(H10:H11) | I12: =SUM(I10:I11) | ... M12: =SUM(M10:M11) | N12: =SUM(B12:M12) | O12: =SUM(O10:O11) | P12: =SUM(P10:P11) | Q12: =SUM(Q10:Q11) | R12: =SUM(R10:R11) | S12: =SUM(N12:R12) | Y12: 8 | Z12: 102 | AA12: 153 | AB12: 51
A13: Utilidad de Operacion | B13: =B8-B12 | C13: =C8-C12 | D13: =D8-D12 | E13: =E8-E12 | F13: =F8-F12 | G13: =G8-G12 | H13: =H8-H12 | I13: =I8-I12 | ... M13: =M8-M12 | N13: =SUM(B13:M13) | O13: =O8-O12 | P13: =P8-P12 | Q13: =Q8-Q12 | R13: =R8-R12 | S13: =S8-S12
A14: Financieros | Y14: Inflación anual (gastos fijos) | Z14: 0.045
A15: Utilidad antes de impuestos | B15: =B13-B14 | C15: =C13-C14 | D15: =D13-D14 | E15: =E13-E14 | F15: =F13-F14 | G15: =G13-G14 | H15: =H13-H14 | I15: =I13-I14 | ... M15: =M13-M14 | N15: =SUM(B15:M15) | O15: =O13-O14 | P15: =P13-P14 | Q15: =Q13-Q14 | R15: =R13-R14 | S15: =S13-S14 | Y15: ISR (México) | Z15: 0.3
A16: Impuestos | N16: =SUM(B16:M16) | O16: =O13*35% | P16: =P13*35% | Q16: =Q13*35% | R16: =R13*35% | S16: =SUM(N16:R16) | Y16: Sueldos de fundadores (100%, anual) | Z16: 600000
A17: Total gastos de operación | B17: =SUM(B10:B11) | C17: =SUM(C10:C11) | D17: =SUM(D10:D11) | E17: =SUM(E10:E11) | F17: =SUM(F10:F11) | G17: =SUM(G10:G11) | H17: =SUM(H10:H11) | I17: =SUM(I10:I11) | ... V17: =SUM(V10:V11) | Y17: Otros costos fijos año 1 (100%, anual) | Z17: 180000
A18: Utilidad de Operación | B18: =B8-B17 | C18: =C8-C17 | D18: =D8-D17 | E18: =E8-E17 | F18: =F8-F17 | G18: =G8-G17 | H18: =H8-H17 | I18: =I8-I17 | ... V18: =V8-V17
A19: Financieros (intereses del crédito — $0 desde año 6, crédito liquidado) | B19: =Amortización!F15 | C19: =Amortización!F16 | D19: =Amortización!F17 | E19: =Amortización!F18 | F19: =Amortización!F19 | G19: =Amortización!F20 | H19: =Amortización!F21 | I19: =Amortización!F22 | J19: =Amortización!F23 | K19: =Amortización!F24 | L19: =Amortización!F25 | M19: =Amortización!F26 | N19: =SUM(B19:M19) | O19: =Amortización!J17 | P19: =Amortización!J18 | Q19: =Amortización!J19 | R19: =Amortización!J20 | S19: =Amortización!J21 | T19: =Amortización!J22 | U19: =Amortización!J23 | V19: =SUM(N19:U19) | Y19: Factor de reducción de sueldos por año (1=100%, 0.5=recorte 50%)
A20: Utilidad antes de impuestos | B20: =B18-B19 | C20: =C18-C19 | D20: =D18-D19 | E20: =E18-E19 | F20: =F18-F19 | G20: =G18-G19 | H20: =H18-H19 | I20: =I18-I19 | ... U20: =U18-U19 | V20: =SUM(N20:U20) | Y20: Año | Z20: Factor
A21: Impuestos (ISR 30%) | B21: =MAX(B20,0)*$Z$15 | C21: =MAX(C20,0)*$Z$15 | D21: =MAX(D20,0)*$Z$15 | E21: =MAX(E20,0)*$Z$15 | F21: =MAX(F20,0)*$Z$15 | G21: =MAX(G20,0)*$Z$15 | H21: =MAX(H20,0)*$Z$15 | I21: =MAX(I20,0)*$Z$15 | ... M21: =MAX(M20,0)*$Z$15 | N21: =SUM(B21:M21) | O21: =MAX(O20,0)*$Z$15 | P21: =MAX(P20,0)*$Z$15 | Q21: =MAX(Q20,0)*$Z$15 | R21: =MAX(R20,0)*$Z$15 | S21: =MAX(S20,0)*$Z$15 | T21: =MAX(T20,0)*$Z$15 | U21: =MAX(U20,0)*$Z$15 | V21: =SUM(N21:U21) | Y21: 1 | Z21: 0.5
A22: Utilidad del Ejercicio | B22: =B20-B21 | C22: =C20-C21 | D22: =D20-D21 | E22: =E20-E21 | F22: =F20-F21 | G22: =G20-G21 | H22: =H20-H21 | I22: =I20-I21 | ... V22: =V20-V21 | Y22: 2 | Z22: 0.5
Y23: 3 | Z23: 1
A24: Rendimiento sobre la inversión (ROI = Utilidad neta acumulada / Inversión inicial, 8 años) | B24: =V22/B26 | Y24: 4 | Z24: 1
Y25: 5 | Z25: 1
A26: Inversión inicial | B26: ='Inversión inicial'!C26 | Y26: 6 | Z26: 1
Y27: 7 | Z27: 1
Y28: 8 | Z28: 1
Y30: Nota: años 6-8 (columnas S-T-U) son una extrapolación de la Tabla 26 al mismo ritmo de crecimiento del último tramo documentado (+50% anual) — no están en el reporte, se muestran para responder "¿en cuántos años es viable AeroGuardia?".

Sheet Flujo de efectivo
A1: FLUJO DE EFECTIVO — AeroGuardia
A3: Ventas | C3: ='Estado de Resultados'!N6 | D3: ='Estado de Resultados'!O6 | E3: ='Estado de Resultados'!P6 | F3: ='Estado de Resultados'!Q6 | G3: ='Estado de Resultados'!R6 | H3: ='Estado de Resultados'!S6 | I3: ='Estado de Resultados'!T6 | J3: ='Estado de Resultados'!U6
A5: CONCEPTO | B5: Año 0 | C5: Total año 1 | D5: Total año 2 | E5: Total año 3 | F5: Total año 4 | G5: Total año 5 | H5: Total año 6 | I5: Total año 7 | J5: Total año 8
A6: Saldo inicial de la cuenta en efectivo (informativo, acumulado) | B6: 0 | C6: =B29 | D6: =C29 | E6: =D29 | F6: =E29 | G6: =F29 | H6: =G29 | I6: =H29 | J6: =I29
A7: Entradas de operación:
A8: Ventas cobradas al contado | C8: =C3 | D8: =D3 | E8: =E3 | F8: =F3 | G8: =G3 | H8: =H3 | I8: =I3 | J8: =J3
A9: Cuentas x cobrar
A10: Otras entradas
A11: Total de entradas de operación | B11: =SUM(B7:B10) | C11: =SUM(C7:C10) | D11: =SUM(D7:D10) | E11: =SUM(E7:E10) | F11: =SUM(F7:F10) | G11: =SUM(G7:G10) | H11: =SUM(H7:H10) | I11: =SUM(I7:I10) | J11: =SUM(J7:J10)
A12: Salidas de operación:
A13: Costo de ventas | C13: ='Estado de Resultados'!N7 | D13: ='Estado de Resultados'!O7 | E13: ='Estado de Resultados'!P7 | F13: ='Estado de Resultados'!Q7 | G13: ='Estado de Resultados'!R7 | H13: ='Estado de Resultados'!S7 | I13: ='Estado de Resultados'!T7 | J13: ='Estado de Resultados'!U7
A14: Gastos de operación (venta + administración) | C14: ='Estado de Resultados'!N17 | D14: ='Estado de Resultados'!O17 | E14: ='Estado de Resultados'!P17 | F14: ='Estado de Resultados'!Q17 | G14: ='Estado de Resultados'!R17 | H14: ='Estado de Resultados'!S17 | I14: ='Estado de Resultados'!T17 | J14: ='Estado de Resultados'!U17
A15: Impuestos (ISR) | C15: ='Estado de Resultados'!N21 | D15: ='Estado de Resultados'!O21 | E15: ='Estado de Resultados'!P21 | F15: ='Estado de Resultados'!Q21 | G15: ='Estado de Resultados'!R21 | H15: ='Estado de Resultados'!S21 | I15: ='Estado de Resultados'!T21 | J15: ='Estado de Resultados'!U21
A16: Otras salidas de operación
A17: Total de salidas | B17: =SUM(B13:B16) | C17: =SUM(C13:C16) | D17: =SUM(D13:D16) | E17: =SUM(E13:E16) | F17: =SUM(F13:F16) | G17: =SUM(G13:G16) | H17: =SUM(H13:H16) | I17: =SUM(I13:I16) | J17: =SUM(J13:J16)
A18: Flujo de efectivo de operación | B18: =B11-B17 | C18: =C11-C17 | D18: =D11-D17 | E18: =E11-E17 | F18: =F11-F17 | G18: =G11-G17 | H18: =H11-H17 | I18: =I11-I17 | J18: =J11-J17
A19: Entradas financieras y de inversión:
A20: Aportaciones de capital | B20: 0
A21: Préstamo bancario | B21: =Amortización!B4
A22: Otras entradas financieras y de inversión
A23: Total de entradas financieras y de inversión: | B23: =SUM(B20:B22) | C23: =SUM(C20:C22) | D23: =SUM(D20:D22) | E23: =SUM(E20:E22) | F23: =SUM(F20:F22) | G23: =SUM(G20:G22) | H23: =SUM(H20:H22) | I23: =SUM(I20:I22) | J23: =SUM(J20:J22)
A24: Salidas financieras y de inversión:
A25: Compra de bienes de capital (inversión inicial) | B25: ='Inversión inicial'!C26
A26: Pago de préstamo e intereses ($0 desde año 6, crédito liquidado) | C26: =Amortización!J16+Amortización!K16 | D26: =Amortización!J17+Amortización!K17 | E26: =Amortización!J18+Amortización!K18 | F26: =Amortización!J19+Amortización!K19 | G26: =Amortización!J20+Amortización!K20 | H26: =Amortización!J21+Amortización!K21 | I26: =Amortización!J22+Amortización!K22 | J26: =Amortización!J23+Amortización!K23
A27: Otras salidas financieras y de inversión
A28: Total de salidas financieras y de inversión | B28: =SUM(B25:B27) | C28: =SUM(C25:C27) | D28: =SUM(D25:D27) | E28: =SUM(E25:E27) | F28: =SUM(F25:F27) | G28: =SUM(G25:G27) | H28: =SUM(H25:H27) | I28: =SUM(I25:I27) | J28: =SUM(J25:J27)
A29: Flujo neto de efectivo del período | B29: =B18+B23-B28-B6 | C29: =C18+C23-C28 | D29: =D18+D23-D28 | E29: =E18+E23-E28 | F29: =F18+F23-F28 | G29: =G18+G23-G28 | H29: =H18+H23-H28 | I29: =I18+I23-I28 | J29: =J18+J23-J28
A30: Saldo final de flujo de efectivo | B30: =B18+B23-B28 | C30: =C18+C23-C28 | D30: =D18+D23-D28 | E30: =E18+E23-E28 | F30: =F18+F23-F28 | G30: =G18+G23-G28

Sheet VAN y TIR
A1: VALOR ACTUAL NETO, TASA INTERNA DE RETORNO, ROI Y HORIZONTE DE VIABILIDAD — AeroGuardia
A3: Inversión Inicial | B3: ='Inversión inicial'!C26
D4: Valor Actual Neto | E4: VAN | G4: Tasa Interna de Retorno | H4: TIR | K4: Recuperación de la inversión
A6: Flujos | D6: Inversión inicial (en negativo) | E6: =B21 | G6: Inversión inicial (en negativo) | H6: =B21 | K6: Año | L6: Flujo neto | M6: Acumulado
A7: F1 | B7: ='Flujo de efectivo'!C29 | D7: Flujos | E7: =+B7 | G7: Flujos | H7: =+E7 | K7: 0 | L7: =B21 | M7: =L7
A8: F2 | B8: ='Flujo de efectivo'!D29 | E8: =+B8 | H8: =+E8 | K8: 1 | L8: =B7 | M8: =M7+L8
A9: F3 | B9: ='Flujo de efectivo'!E29 | E9: =+B9 | H9: =+E9 | K9: 2 | L9: =B8 | M9: =M8+L9
A10: F4 | B10: ='Flujo de efectivo'!F29 | E10: =+B10 | H10: =+E10 | K10: 3 | L10: =B9 | M10: =M9+L10
A11: F5 | B11: ='Flujo de efectivo'!G29 | E11: =+B11 | H11: =+E11 | K11: 4 | L11: =B10 | M11: =M10+L11
A12: F6 | B12: ='Flujo de efectivo'!H29 | E12: =+B12 | H12: =+E12 | K12: 5 | L12: =B11 | M12: =M11+L12
A13: F7 | B13: ='Flujo de efectivo'!I29 | E13: =+B13 | H13: =+E13 | K13: 6 | L13: =B12 | M13: =M12+L13
A14: F8 | B14: ='Flujo de efectivo'!J29 | E14: =+B14 | H14: =+E14 | K14: 7 | L14: =B13 | M14: =M13+L14
A15: F9 | E15: =+B15 | H15: =+E15 | K15: 8 | L15: =B14 | M15: =M14+L15
A16: F10 | E16: =+B16 | H16: =+E16
A17: F11 | E17: =+B17 | H17: =+E17 | K17: Periodo de recuperación simple (sin descuento, años) | M17: =IFERROR(IF(M8>=0,1+((-M7)/L8),IF(M9>=0,2+((-M8)/L9),IF(M10>=0,3+((-M9)/L10),IF(M11>=0,4+((-M10)/L11),IF(M12>=0,5+((-M11)/L12),IF(M13>=0,6+((-M12)/L13),IF(M14>=0,7+((-M13)/L14),IF(M15>=0,8+((-M14)/L15),"No se recupera en el horizonte analizado")))))))),"No se recupera en el horizonte analizado")
A18: F12 | E18: =+B18 | H18: =+E18
A19: n (años proyectados) | B19: 8
A20: k = tasa de descuento (costo de la deuda, 100% financiado) | B20: 0.115 | E20: VAN a 5 años | F20: =NPV(B20,E7:E11)+E6 | H20: TIR a 5 años | I20: =IRR(H6:H11)
A21: Inversión inicial en negativo | B21: =-B3 | E21: VAN a 8 años | F21: =NPV(B20,E7:E14)+E6 | H21: TIR a 8 años | I21: =IRR(H6:H14)
A23: ROI a 8 años (Utilidad acumulada / Inversión inicial) | B23: ='Estado de Resultados'!B24
D25: El proyecto a 5 años es: | E25: =IF(F20>0,IF(I20>B20,"VIABLE","NO VIABLE"),"NO VIABLE")
D26: El proyecto a 8 años es: | E26: =IF(F21>0,IF(I21>B20,"VIABLE","NO VIABLE"),"NO VIABLE")
A28: ¿En cuántos años es viable AeroGuardia? El VAN se vuelve positivo entre los años 6 y 7 (ver F20/F21 y la tabla de VAN por horizonte abajo) — el proyecto NO es viable a 5 años bajo el criterio estándar VAN/TIR, pero SÍ es viable a mediano plazo.
A30: VAN por horizonte (n años) | B30: Año | C30: VAN acumulado a ese horizonte
B31: 1 | C31: =NPV($B$20,$E$7:$E7)+$E$6
B32: 2 | C32: =NPV($B$20,$E$7:$E8)+$E$6
B33: 3 | C33: =NPV($B$20,$E$7:$E9)+$E$6
B34: 4 | C34: =NPV($B$20,$E$7:$E10)+$E$6
B35: 5 | C35: =NPV($B$20,$E$7:$E11)+$E$6
B36: 6 | C36: =NPV($B$20,$E$7:$E12)+$E$6
B37: 7 | C37: =NPV($B$20,$E$7:$E13)+$E$6
B38: 8 | C38: =NPV($B$20,$E$7:$E14)+$E$6

Sheet Amortización
A1: Tabla de amortización del crédito
A2: Entidad financiera: crédito empresarial PYME a 5 años (se liquida al final del año 5)
A4: Importe del préstamo (MXN) | B4: ='Inversión inicial'!D32
A5: Interés anual nominal | B5: 0.115
A6: Plazo (años) | B6: 5
A7: Pagos por año | B7: 12
A8: Número total de pagos | B8: =B6*B7
A9: Tasa mensual | B9: =B5/B7
A10: Pago mensual (PMT) | B10: =-PMT(B9,B8,B4)
A11: Interés total del crédito | B11: =B10*B8-B4
A14: Pago Nº | B14: Año | C14: Saldo inicial | D14: Pago mensual | E14: Capital | F14: Intereses | G14: Saldo final | I14: Resumen anual
A15: 1 | B15: =ROUNDUP(A15/12,0) | C15: =$B$4 | D15: =$B$10 | E15: =D15-F15 | F15: =C15*$B$9 | G15: =C15-E15 | I15: Año | J15: Interés del año | K15: Capital del año
A16: 2 | B16: =ROUNDUP(A16/12,0) | C16: =G15 | D16: =$B$10 | E16: =D16-F16 | F16: =C16*$B$9 | G16: =C16-E16 | I16: 1 | J16: =SUMIF($B$15:$B$74,I16,$F$15:$F$74) | K16: =SUMIF($B$15:$B$74,I16,$E$15:$E$74)
A17: 3 | B17: =ROUNDUP(A17/12,0) | C17: =G16 | D17: =$B$10 | E17: =D17-F17 | F17: =C17*$B$9 | G17: =C17-E17 | I17: 2 | J17: =SUMIF($B$15:$B$74,I17,$F$15:$F$74) | K17: =SUMIF($B$15:$B$74,I17,$E$15:$E$74)
A18: 4 | B18: =ROUNDUP(A18/12,0) | C18: =G17 | D18: =$B$10 | E18: =D18-F18 | F18: =C18*$B$9 | G18: =C18-E18 | I18: 3 | J18: =SUMIF($B$15:$B$74,I18,$F$15:$F$74) | K18: =SUMIF($B$15:$B$74,I18,$E$15:$E$74)
A19: 5 | B19: =ROUNDUP(A19/12,0) | C19: =G18 | D19: =$B$10 | E19: =D19-F19 | F19: =C19*$B$9 | G19: =C19-E19 | I19: 4 | J19: =SUMIF($B$15:$B$74,I19,$F$15:$F$74) | K19: =SUMIF($B$15:$B$74,I19,$E$15:$E$74)
A20: 6 | B20: =ROUNDUP(A20/12,0) | C20: =G19 | D20: =$B$10 | E20: =D20-F20 | F20: =C20*$B$9 | G20: =C20-E20 | I20: 5 | J20: =SUMIF($B$15:$B$74,I20,$F$15:$F$74) | K20: =SUMIF($B$15:$B$74,I20,$E$15:$E$74)
A21: 7 | B21: =ROUNDUP(A21/12,0) | C21: =G20 | D21: =$B$10 | E21: =D21-F21 | F21: =C21*$B$9 | G21: =C21-E21 | I21: 6 | J21: =SUMIF($B$15:$B$74,I21,$F$15:$F$74) | K21: =SUMIF($B$15:$B$74,I21,$E$15:$E$74)
A22: 8 | B22: =ROUNDUP(A22/12,0) | C22: =G21 | D22: =$B$10 | E22: =D22-F22 | F22: =C22*$B$9 | G22: =C22-E22 | I22: 7 | J22: =SUMIF($B$15:$B$74,I22,$F$15:$F$74) | K22: =SUMIF($B$15:$B$74,I22,$E$15:$E$74)
A23: 9 | B23: =ROUNDUP(A23/12,0) | C23: =G22 | D23: =$B$10 | E23: =D23-F23 | F23: =C23*$B$9 | G23: =C23-E23 | I23: 8 | J23: =SUMIF($B$15:$B$74,I23,$F$15:$F$74) | K23: =SUMIF($B$15:$B$74,I23,$E$15:$E$74)
A24: 10 | B24: =ROUNDUP(A24/12,0) | C24: =G23 | D24: =$B$10 | E24: =D24-F24 | F24: =C24*$B$9 | G24: =C24-E24
A25: 11 | B25: =ROUNDUP(A25/12,0) | C25: =G24 | D25: =$B$10 | E25: =D25-F25 | F25: =C25*$B$9 | G25: =C25-E25
A26: 12 | B26: =ROUNDUP(A26/12,0) | C26: =G25 | D26: =$B$10 | E26: =D26-F26 | F26: =C26*$B$9 | G26: =C26-E26
A27: 13 | B27: =ROUNDUP(A27/12,0) | C27: =G26 | D27: =$B$10 | E27: =D27-F27 | F27: =C27*$B$9 | G27: =C27-E27
A28: 14 | B28: =ROUNDUP(A28/12,0) | C28: =G27 | D28: =$B$10 | E28: =D28-F28 | F28: =C28*$B$9 | G28: =C28-E28
A29: 15 | B29: =ROUNDUP(A29/12,0) | C29: =G28 | D29: =$B$10 | E29: =D29-F29 | F29: =C29*$B$9 | G29: =C29-E29
A30: 16 | B30: =ROUNDUP(A30/12,0) | C30: =G29 | D30: =$B$10 | E30: =D30-F30 | F30: =C30*$B$9 | G30: =C30-E30
A31: 17 | B31: =ROUNDUP(A31/12,0) | C31: =G30 | D31: =$B$10 | E31: =D31-F31 | F31: =C31*$B$9 | G31: =C31-E31
A32: 18 | B32: =ROUNDUP(A32/12,0) | C32: =G31 | D32: =$B$10 | E32: =D32-F32 | F32: =C32*$B$9 | G32: =C32-E32
A33: 19 | B33: =ROUNDUP(A33/12,0) | C33: =G32 | D33: =$B$10 | E33: =D33-F33 | F33: =C33*$B$9 | G33: =C33-E33
A34: 20 | B34: =ROUNDUP(A34/12,0) | C34: =G33 | D34: =$B$10 | E34: =D34-F34 | F34: =C34*$B$9 | G34: =C34-E34
A35: 21 | B35: =ROUNDUP(A35/12,0) | C35: =G34 | D35: =$B$10 | E35: =D35-F35 | F35: =C35*$B$9 | G35: =C35-E35
... A74: 60 | B74: =ROUNDUP(A74/12,0) | C74: =G73 | D74: =$B$10 | E74: =D74-F74 | F74: =C74*$B$9 | G74: =C74-E74
A76: Totales | D76: =SUM(D15:D74) | E76: =SUM(E15:E74) | F76: =SUM(F15:F74)
