Workbook

Sheet Inversión inicial
B2: AeroGuardia
B4: CÁLCULO DE LA INVERSIÓN INICIAL
B6: CONCEPTO | C6: CANTIDAD
B7: Desarrollo inicial del software | C7: 250000
B8: Auditoría y pruebas de ciberseguridad | C8: 80000
B9: Diseño de interfaz y experiencia de usuario (UI/UX) | C9: 30000
B10: Infraestructura tecnológica inicial | C10: 20000
B11: Registro de marca y asesoría legal | C11: 25000
B12: Desarrollo de sitio web corporativo | C12: 15000
B13: Equipo demostrativo de hardware | C13: 30000
B14: Fondo operativo inicial | C14: 50000
B15: Equipo de transporte y entrega | C15: 0
B16: Activos diferidos
B17: Depósito y renta | C17: 0
B18: Gastos de instalación (remodelaciones) | C18: 0
B19: Gastos de organización (notario, permisos, escrituras, honorarios, etc.) | C19: 0
B20: Gastos para iniciar operaciones (papelería, consumibles, artículos varios) | C20: 0
B21: Gastos de mercadotecnia | C21: 0
B22: Activos intangibles
B23: Patentes y marcas | C23: 0
B24: Dominios de internet | C24: 0
B25: Licencias de uso (software) | C25: 0
B26: TOTAL DE INVERSIÓN INICIAL | C26: =SUM(C7:C14) -> 500000
B29: ESTRUCTURA FINANCIERA | D29: $(MXN)
B31: Patrimonio propio | C31: 0 | D31: =C26*C31 -> 0
B32: Recursos ajenos (crédito) | C32: 1 | D32: =C26*C32 -> 500000

Sheet  Proyeccion de ventas en unidad
A2: AeroGuardia
A4: PRONÓSTICO DE NUEVAS IMPLEMENTACIONES (CLIENTES NUEVOS) — AÑO 1
A5: MES | B5: CLIENTES NUEVOS (IMPLEMENTACIONES)
A6: ENERO | B6: 0
A7: FEBRERO | B7: 1
A8: MARZO | B8: 0
A9: ABRIL | B9: 1
A10: MAYO | B10: 0
A11: JUNIO | B11: 1
A12: JULIO | B12: 0
A13: AGOSTO | B13: 1
A14: SEPTIEMBRE | B14: 0
A15: OCTUBRE | B15: 1
A16: NOVIEMBRE | B16: 0
A17: DICIEMBRE | B17: 0
A18: Totales | B18: =SUM(B6:B17) -> 5
A20: Clientes el primer año | B20: 5

Sheet Presupuesto de operación
A1: PRESUPUESTO DE OPERACIÓN
A3: AeroGuardia
A5: Precios de venta | B5: Primer semestre
A6: Cuota de implementación (por cliente nuevo) | B6: ='Costos y precio de venta'!B71 -> 25500
A8: Ventas presupuestadas en unidades el primer año (clientes nuevos)
A10: Concepto | B10: Primer año
A11: Implementaciones nuevas | B11: 5
A12: Total | B12: =SUM(B11:B11) -> 5
A14: 1.- Presupuesto de ventas por implementación
A16: Servicio | B16: Primer Año
A17: Cuota de implementación | B17: =B6*B12 -> 127500
A18: Total | B18: =SUM(B17:B17) -> 127500
A20: Suscripción mensual | B20: Precio | C20: Costo variable
A21: Precio de suscripción / costo operativo por cliente | B21: ='Costos y precio de venta'!B74 -> 4500 | C21: ='Costos y precio de venta'!B73 -> 500
A23: 2.-Presupuesto de gastos de venta anuales (100%, sin recorte)
A25: Concepto | B25: Cantidad
A26: Sueldo Director de Operaciones y Desarrollo Comercial | B26: ='Costos y precio de venta'!B10 -> 240000
A27: Publicidad y promoción digital | B27: ='Costos y precio de venta'!B11 -> 60000
A28: Total | B28: =SUM(B26:B27) -> 300000
A30: 3.-Presupuesto de gastos de administración anuales (100%, sin recorte)
A32: Concepto | B32: Cantidad
A33: Sueldo Director General (CEO) y Director de Desarrollo | B33: ='Costos y precio de venta'!B27 -> 360000
A34: Hospedaje de la plataforma | B34: ='Costos y precio de venta'!B28 -> 30000
A35: Bases de datos y almacenamiento | B35: ='Costos y precio de venta'!B29 -> 18000
A36: Dominio, correo empresarial y certificados SSL | B36: ='Costos y precio de venta'!B30 -> 6000
A37: Licencias y herramientas de desarrollo | B37: ='Costos y precio de venta'!B31 -> 18000
A38: Servicios contables y administrativos | B38: ='Costos y precio de venta'!B32 -> 36000
A39: Internet y comunicaciones | B39: ='Costos y precio de venta'!B33 -> 12000
A40: Total | B40: =SUM(B33:B39) -> 480000
A42: Nota: los años 1-2 aplican un recorte del 50% sobre los $50,000/mes de sueldos de
A43: fundadores (ver hoja 'Estado de Resultados'); esta hoja muestra los montos anuales al 100%.
A45: Pago mensual del crédito (Financieros, no es gasto de operación — ver Estado de Resultados) | B45: =Amortización!B10*12 -> 131955.64

Sheet Costos y precio de venta
A1: DETERMINACIÓN DEL PRECIO DE VENTA — AeroGuardia
A3: Sueldos de fundadores (Director General $30,000 + Director de Operaciones $20,000 = $50,000/mes) recortados 50% en años 1-2 mientras el negocio gana tracción
A7: 2.-Presupuesto de gastos de venta
A9: Concepto | B9: Cantidad
A10: Director de Operaciones y Desarrollo Comercial (sueldo anual, 100%) | B10: 240000
A11: Publicidad y promoción digital | B11: 60000
A12: Seguro social | B12: 7000
A13: Agua | B13: 500
A14: Luz | B14: 1000
A15: Teléfono | B15: 240
A16: Renta | B16: 1500
A17: Internet | B17: 150
A18: Mantenimiento de equipo de entrega | B18: 500
A19: Depreciaciones | B19: 500
A20: Publicidad y promoción | B20: 3000
A21: Gasolina | B21: 5000
A22: Total | B22: =SUM(B10:B11) -> 300000
A24: 3.- Gastos de administración
A26: Concepto | B26: Cantidad
A27: Director General (CEO) y Director de Desarrollo (sueldo anual, 100%) | B27: 360000
A28: Hospedaje de la plataforma (cloud hosting) | B28: 30000
A29: Bases de datos y almacenamiento | B29: 18000
A30: Dominio, correo empresarial y certificados SSL | B30: 6000
A31: Licencias y herramientas de desarrollo | B31: 18000
A32: Servicios contables y administrativos | B32: 36000
A33: Internet y comunicaciones | B33: 12000
A34: Papelería y útiles de oficina | B34: 350
A35: Depreciaciones | B35: 500
A36: Total | B36: =SUM(B27:B33) -> 480000
A38: Total costos fijos anuales (100%, sin recorte) | B38: =B22+B36 -> 780000
A40: Sueldos de fundadores (subtotal, 100%) | B40: 600000
A41: Otros costos fijos (no se recortan) | B41: =B38-B40 -> 180000
A43: Insumos directos x servicio (hardware e instalación, Tabla 18) | B43: 12450
A44: Sueldos directos x servicio (servicios de implementación, Tabla 19) | B44: 5750
A45: Costo variable unitario (costo real de implementación) | B45: =SUM(B43:B44) -> 18200
A48: Determinación del precio
A50: Datos:
A51: Costos fijos | B51: =B38 -> 780000
A52: Costo variable unitario | B52: =B45 -> 18200
A53: Ventas esperadas (implementaciones) por mes | B53: ='Presupuesto de operación'!B12 -> 5
...

Sheet Ventas presupuestadas en $
B1: VENTAS PRESUPUESTADAS AÑO 1 EN $ — AeroGuardia
B3: Concepto | C3: Enero | D3: Febrero | E3: Marzo | F3: Abril | G3: Mayo | H3: Junio | I3: Julio | J3: Agosto | K3: Septiembre | L3: Octubre | M3: Noviembre | N3: Diciembre | O3: Total
B4: Clientes nuevos (implementaciones) | C4: =' Proyeccion de ventas en unidad'!B6 -> 0 | D4: =' Proyeccion de ventas en unidad'!B7 -> 1 | E4: =' Proyeccion de ventas en unidad'!B8 -> 0 | F4: =' Proyeccion de ventas en unidad'!B9 -> 1 | G4: =' Proyeccion de ventas en unidad'!B10 -> 0 | H4: =' Proyeccion de ventas en unidad'!B11 -> 1 | I4: =' Proyeccion de ventas en unidad'!B12 -> 0 | J4: =' Proyeccion de ventas en unidad'!B13 -> 1 | K4: =' Proyeccion de ventas en unidad'!B14 -> 0 | L4: =' Proyeccion de ventas en unidad'!B15 -> 1 | M4: =' Proyeccion de ventas en unidad'!B16 -> 0 | N4: =' Proyeccion de ventas en unidad'!B17 -> 0 | O4: =SUM(C4:N4) -> 5
B5: Clientes activos (acumulado) | C5: =C4 -> 0 | D5: =C5+D4 -> 1 | E5: =D5+E4 -> 1 | F5: =E5+F4 -> 2 | G5: =F5+G4 -> 2 | H5: =G5+H4 -> 3 | I5: =H5+I4 -> 3 | J5: =I5+J4 -> 4 | K5: =J5+K4 -> 4 | ... N5: =M5+N4 -> 5
B6: Precio de implementación | C6: ='Costos y precio de venta'!$B$71 -> 25500 | D6: ='Costos y precio de venta'!$B$71 -> 25500 | E6: ='Costos y precio de venta'!$B$71 -> 25500 | F6: ='Costos y precio de venta'!$B$71 -> 25500 | G6: ='Costos y precio de venta'!$B$71 -> 25500 | H6: ='Costos y precio de venta'!$B$71 -> 25500 | I6: ='Costos y precio de venta'!$B$71 -> 25500 | J6: ='Costos y precio de venta'!$B$71 -> 25500 | ... N6: ='Costos y precio de venta'!$B$71 -> 25500 | O6: =SUM(C6:N6) -> 306000
B7: Ingreso por implementación | C7: =C4*C6 -> 0 | D7: =D4*D6 -> 25500 | E7: =E4*E6 -> 0 | F7: =F4*F6 -> 25500 | G7: =G4*G6 -> 0 | H7: =H4*H6 -> 25500 | I7: =I4*I6 -> 0 | J7: =J4*J6 -> 25500 | ... N7: =N4*N6 -> 0 | O7: =SUM(C7:N7) -> 127500
B8: Precio de suscripción mensual | C8: ='Costos y precio de venta'!$B$74 -> 4500 | D8: ='Costos y precio de venta'!$B$74 -> 4500 | E8: ='Costos y precio de venta'!$B$74 -> 4500 | F8: ='Costos y precio de venta'!$B$74 -> 4500 | G8: ='Costos y precio de venta'!$B$74 -> 4500 | H8: ='Costos y precio de venta'!$B$74 -> 4500 | I8: ='Costos y precio de venta'!$B$74 -> 4500 | J8: ='Costos y precio de venta'!$B$74 -> 4500 | ... N8: ='Costos y precio de venta'!$B$74 -> 4500
B9: Ingreso por suscripción | C9: =C5*C8 -> 0 | D9: =D5*D8 -> 4500 | E9: =E5*E8 -> 4500 | F9: =F5*F8 -> 9000 | G9: =G5*G8 -> 9000 | H9: =H5*H8 -> 13500 | I9: =I5*I8 -> 13500 | J9: =J5*J8 -> 18000 | ... N9: =N5*N8 -> 22500 | O9: =SUM(C9:N9) -> 157500
B10: Total ventas | C10: =C7+C9 -> 0 | D10: =D7+D9 -> 30000 | E10: =E7+E9 -> 4500 | F10: =F7+F9 -> 34500 | G10: =G7+G9 -> 9000 | H10: =H7+H9 -> 39000 | I10: =I7+I9 -> 13500 | J10: =J7+J9 -> 43500 | ... N10: =N7+N9 -> 22500 | O10: =SUM(C10:N10) -> 285000
B12: Costo variable de implementación | C12: ='Costos y precio de venta'!$B$45 -> 18200 | D12: ='Costos y precio de venta'!$B$45 -> 18200 | E12: ='Costos y precio de venta'!$B$45 -> 18200 | F12: ='Costos y precio de venta'!$B$45 -> 18200 | G12: ='Costos y precio de venta'!$B$45 -> 18200 | H12: ='Costos y precio de venta'!$B$45 -> 18200 | I12: ='Costos y precio de venta'!$B$45 -> 18200 | J12: ='Costos y precio de venta'!$B$45 -> 18200 | ... N12: ='Costos y precio de venta'!$B$45 -> 18200
B13: Costo de implementación (COGS) | C13: =C4*C12 -> 0 | D13: =D4*D12 -> 18200 | E13: =E4*E12 -> 0 | F13: =F4*F12 -> 18200 | G13: =G4*G12 -> 0 | H13: =H4*H12 -> 18200 | I13: =I4*I12 -> 0 | J13: =J4*J12 -> 18200 | ... N13: =N4*N12 -> 0 | O13: =SUM(C13:N13) -> 91000
B14: Costo operativo mensual por cliente activo | C14: ='Costos y precio de venta'!$B$73 -> 500 | D14: ='Costos y precio de venta'!$B$73 -> 500 | E14: ='Costos y precio de venta'!$B$73 -> 500 | F14: ='Costos y precio de venta'!$B$73 -> 500 | G14: ='Costos y precio de venta'!$B$73 -> 500 | H14: ='Costos y precio de venta'!$B$73 -> 500 | I14: ='Costos y precio de venta'!$B$73 -> 500 | J14: ='Costos y precio de venta'!$B$73 -> 500 | ... N14: ='Costos y precio de venta'!$B$73 -> 500
B15: Costo operativo de clientes activos | C15: =C5*C14 -> 0 | D15: =D5*D14 -> 500 | E15: =E5*E14 -> 500 | F15: =F5*F14 -> 1000 | G15: =G5*G14 -> 1000 | H15: =H5*H14 -> 1500 | I15: =I5*I14 -> 1500 | J15: =J5*J14 -> 2000 | ... N15: =N5*N14 -> 2500 | O15: =SUM(C15:N15) -> 17500
B16: Costo de ventas total | C16: =C13+C15 -> 0 | D16: =D13+D15 -> 18700 | E16: =E13+E15 -> 500 | F16: =F13+F15 -> 19200 | G16: =G13+G15 -> 1000 | H16: =H13+H15 -> 19700 | I16: =I13+I15 -> 1500 | J16: =J13+J15 -> 20200 | ... N16: =N13+N15 -> 2500 | O16: =SUM(C16:N16) -> 108500

Sheet Estado de Resultados
A2: AeroGuardia
A4: ESTADO DE RESULTADOS PRESUPUESTADO | B4: AÑO 1 | O4: PROYECCIÓN POR CRECIMIENTO DE CARTERA DE CLIENTES (Tabla 26 del reporte, años 2-5) | P4: INCREMENTO DE VENTAS DEL 10% | Q4: INCREMENTO DE VENTAS DEL 15% | R4: INCREMENTO DE VENTAS DEL 25% | S4: AÑOS 6-8: EXTRAPOLACIÓN (no está en el reporte — ver nota) | V4: TOTAL 8 AÑOS
B5: Enero | C5: Febrero | D5: Marzo | E5: Abril | F5: Mayo | G5: Junio | H5: Julio | I5: Agosto | J5: Septiembre | K5: Octubre | L5: Noviembre | M5: Diciembre | N5: Total año 1 | O5: AÑO 2 | P5: AÑO 3 | Q5: AÑO 4 | R5: AÑO 5 | S5: AÑO 6 | T5: AÑO 7 | U5: AÑO 8
A6: Ventas | B6: ='Ventas presupuestadas en $'!C10 -> 0 | C6: ='Ventas presupuestadas en $'!D10 -> 30000 | D6: ='Ventas presupuestadas en $'!E10 -> 4500 | E6: ='Ventas presupuestadas en $'!F10 -> 34500 | F6: ='Ventas presupuestadas en $'!G10 -> 9000 | G6: ='Ventas presupuestadas en $'!H10 -> 39000 | H6: ='Ventas presupuestadas en $'!I10 -> 13500 | I6: ='Ventas presupuestadas en $'!J10 -> 43500 | ... M6: ='Ventas presupuestadas en $'!N10 -> 22500 | N6: =SUM(B6:M6) -> 285000 | O6: =((B23+C23)/2)*'Costos y precio de venta'!$B$74*12+D23*'Costos y precio de venta'!$B$71 -> 637500 | P6: =((B24+C24)/2)*'Costos y precio de venta'!$B$74*12+D24*'Costos y precio de venta'!$B$71 -> 1068000 | Q6: =((B25+C25)/2)*'Costos y precio de venta'!$B$74*12+D25*'Costos y precio de venta'!$B$71 -> 1605000 | R6: =((B26+C26)/2)*'Costos y precio de venta'!$B$74*12+D26*'Costos y precio de venta'!$B$71 -> 2407500 | S6: =((B27+C27)/2)*'Costos y precio de venta'!$B$74*12+D27*'Costos y precio de venta'!$B$71 -> 3637500 | T6: =((B28+C28)/2)*'Costos y precio de venta'!$B$74*12+D28*'Costos y precio de venta'!$B$71 -> 5457000 | U6: =((B29+C29)/2)*'Costos y precio de venta'!$B$74*12+D29*'Costos y precio de venta'!$B$71 -> 8185500 | V6: =SUM(N6:U6) -> 23283000
A7: Costo de Ventas | B7: ='Ventas presupuestadas en $'!C16 -> 0 | C7: ='Ventas presupuestadas en $'!D16 -> 18700 | D7: ='Ventas presupuestadas en $'!E16 -> 500 | E7: ='Ventas presupuestadas en $'!F16 -> 19200 | F7: ='Ventas presupuestadas en $'!G16 -> 1000 | G7: ='Ventas presupuestadas en $'!H16 -> 19700 | H7: ='Ventas presupuestadas en $'!I16 -> 1500 | I7: ='Ventas presupuestadas en $'!J16 -> 20200 | ... M7: ='Ventas presupuestadas en $'!N16 -> 2500 | N7: =SUM(B7:M7) -> 108500 | O7: =((B23+C23)/2)*'Costos y precio de venta'!$B$73*12+D23*'Costos y precio de venta'!$B$45 -> 178400 | P7: =((B24+C24)/2)*'Costos y precio de venta'!$B$73*12+D24*'Costos y precio de venta'!$B$45 -> 241600 | Q7: =((B25+C25)/2)*'Costos y precio de venta'!$B$73*12+D25*'Costos y precio de venta'!$B$45 -> 332000 | R7: =((B26+C26)/2)*'Costos y precio de venta'!$B$73*12+D26*'Costos y precio de venta'!$B$45 -> 498000 | S7: =((B27+C27)/2)*'Costos y precio de venta'!$B$73*12+D27*'Costos y precio de venta'!$B$45 -> 757600 | T7: =((B28+C28)/2)*'Costos y precio de venta'!$B$73*12+D28*'Costos y precio de venta'!$B$45 -> 1128800 | U7: =((B29+C29)/2)*'Costos y precio de venta'!$B$73*12+D29*'Costos y precio de venta'!$B$45 -> 1693200 | V7: =SUM(N7:U7) -> 4938100
A8: Utilidad Bruta | B8: =B6-B7 -> 0 | C8: =C6-C7 -> 11300 | D8: =D6-D7 -> 4000 | E8: =E6-E7 -> 15300 | F8: =F6-F7 -> 8000 | G8: =G6-G7 -> 19300 | H8: =H6-H7 -> 12000 | I8: =I6-I7 -> 23300 | ... V8: =V6-V7 -> 18344900
A9: Sueldos de fundadores (con recorte años 1-2) | B9: =($B$33/12)*$B$38 -> 25000 | C9: =($B$33/12)*$B$38 -> 25000 | D9: =($B$33/12)*$B$38 -> 25000 | E9: =($B$33/12)*$B$38 -> 25000 | F9: =($B$33/12)*$B$38 -> 25000 | G9: =($B$33/12)*$B$38 -> 25000 | H9: =($B$33/12)*$B$38 -> 25000 | I9: =($B$33/12)*$B$38 -> 25000 | ... M9: =($B$33/12)*$B$38 -> 25000 | N9: =SUM(B9:M9) -> 300000 | O9: =$B$33*(1+$B$31)^1*$B$39 -> 313500 | P9: =$B$33*(1+$B$31)^2*$B$40 -> 655215 | Q9: =$B$33*(1+$B$31)^3*$B$41 -> 684699.67 | R9: =$B$33*(1+$B$31)^4*$B$42 -> 715511.16 | S9: =$B$33*(1+$B$31)^5*$B$43 -> 747709.16 | T9: =$B$33*(1+$B$31)^6*$B$44 -> 781356.07 | U9: =$B$33*(1+$B$31)^7*$B$45 -> 816517.1 | V9: =SUM(N9:U9) -> 5014508.2
A10: Otros gastos fijos (venta + administración, sin recorte) | B10: =$B$34/12 -> 15000 | C10: =$B$34/12 -> 15000 | D10: =$B$34/12 -> 15000 | E10: =$B$34/12 -> 15000 | F10: =$B$34/12 -> 15000 | G10: =$B$34/12 -> 15000 | H10: =$B$34/12 -> 15000 | I10: =$B$34/12 -> 15000 | ... M10: =$B$34/12 -> 15000 | N10: =SUM(B10:M10) -> 180000 | O10: =$B$34*(1+$B$31)^1 -> 188100 | P10: =$B$34*(1+$B$31)^2 -> 196564.5 | Q10: =$B$34*(1+$B$31)^3 -> 205409.9 | R10: =$B$34*(1+$B$31)^4 -> 214653.35 | S10: =$B$34*(1+$B$31)^5 -> 224312.75 | T10: =$B$34*(1+$B$31)^6 -> 234406.82 | U10: =$B$34*(1+$B$31)^7 -> 244955.13 | V10: =SUM(N10:U10) -> 1688402.5
A11: Total gastos de operación | B11: =SUM(B9:B10) -> 40000 | C11: =SUM(C9:C10) -> 40000 | D11: =SUM(D9:D10) -> 40000 | E11: =SUM(E9:E10) -> 40000 | F11: =SUM(F9:F10) -> 40000 | G11: =SUM(G9:G10) -> 40000 | H11: =SUM(H9:H10) -> 40000 | I11: =SUM(I9:I10) -> 40000 | ... V11: =SUM(V9:V10) -> 6702910.6
A12: Utilidad de Operación | B12: =B8-B11 -> -40000 | C12: =C8-C11 -> -28700 | D12: =D8-D11 -> -36000 | E12: =E8-E11 -> -24700 | F12: =F8-F11 -> -32000 | G12: =G8-G11 -> -20700 | H12: =H8-H11 -> -28000 | I12: =I8-I11 -> -16700 | ... V12: =V8-V11 -> 11641989
A13: Financieros (intereses del crédito — $0 desde año 6, crédito liquidado) | B13: =Amortización!F15 -> 4791.6667 | C13: =Amortización!F16 -> 4732.2056 | D13: =Amortización!F17 -> 4672.1746 | E13: =Amortización!F18 -> 4611.5684 | F13: =Amortización!F19 -> 4550.3813 | G13: =Amortización!F20 -> 4488.6079 | H13: =Amortización!F21 -> 4426.2425 | I13: =Amortización!F22 -> 4363.2794 | J13: =Amortización!F23 -> 4299.7129 | K13: =Amortización!F24 -> 4235.5373 | L13: =Amortización!F25 -> 4170.7466 | M13: =Amortización!F26 -> 4105.335 | N13: =SUM(B13:M13) -> 53447.458 | O13: =Amortización!J17 -> 43927.608 | P13: =Amortización!J18 -> 33253.388 | Q13: =Amortización!J19 -> 21284.818 | R13: =Amortización!J20 -> 7864.9485 | S13: =Amortización!J21 -> 0 | T13: =Amortización!J22 -> 0 | U13: =Amortización!J23 -> 0 | V13: =SUM(N13:U13) -> 159778.22
A14: Utilidad antes de impuestos | B14: =B12-B13 -> -44791.667 | C14: =C12-C13 -> -33432.206 | D14: =D12-D13 -> -40672.175 | E14: =E12-E13 -> -29311.568 | F14: =F12-F13 -> -36550.381 | G14: =G12-G13 -> -25188.608 | H14: =H12-H13 -> -32426.242 | I14: =I12-I13 -> -21063.279 | ... U14: =U12-U13 -> 5430827.8 | V14: =SUM(N14:U14) -> 11482211
A15: Impuestos (ISR 30%) | B15: =MAX(B14,0)*$B$32 -> 0 | C15: =MAX(C14,0)*$B$32 -> 0 | D15: =MAX(D14,0)*$B$32 -> 0 | E15: =MAX(E14,0)*$B$32 -> 0 | F15: =MAX(F14,0)*$B$32 -> 0 | G15: =MAX(G14,0)*$B$32 -> 0 | H15: =MAX(H14,0)*$B$32 -> 0 | I15: =MAX(I14,0)*$B$32 -> 0 | ... M15: =MAX(M14,0)*$B$32 -> 0 | N15: =SUM(B15:M15) -> 0 | O15: =MAX(O14,0)*$B$32 -> 0 | P15: =MAX(P14,0)*$B$32 -> 0 | Q15: =MAX(Q14,0)*$B$32 -> 108481.68 | R15: =MAX(R14,0)*$B$32 -> 291441.16 | S15: =MAX(S14,0)*$B$32 -> 572363.43 | T15: =MAX(T14,0)*$B$32 -> 993731.13 | U15: =MAX(U14,0)*$B$32 -> 1629248.3 | V15: =SUM(N15:U15) -> 3595265.7
A16: Utilidad del Ejercicio | B16: =B14-B15 -> -44791.667 | C16: =C14-C15 -> -33432.206 | D16: =D14-D15 -> -40672.175 | E16: =E14-E15 -> -29311.568 | F16: =F14-F15 -> -36550.381 | G16: =G14-G15 -> -25188.608 | H16: =H14-H15 -> -32426.242 | I16: =I14-I15 -> -21063.279 | ... V16: =V14-V15 -> 7886945.4
A18: Rendimiento sobre la inversión (ROI = Utilidad neta acumulada / Inversión inicial, 8 años) | B18: =V16/B19 -> 15.773891
A19: Inversión inicial | B19: ='Inversión inicial'!C26 -> 500000
A21: Supuestos años 2-8
A22: Año | B22: Clientes inicio | C22: Clientes fin | D22: Clientes nuevos
A23: 2 | B23: 5 | C23: 12 | D23: 7
A24: 3 | B24: 12 | C24: 20 | D24: 8
A25: 4 | B25: 20 | C25: 30 | D25: 10
A26: 5 | B26: 30 | C26: 45 | D26: 15
A27: 6 | B27: 45 | C27: 68 | D27: 23
A28: 7 | B28: 68 | C28: 102 | D28: 34
A29: 8 | B29: 102 | C29: 153 | D29: 51
A31: Inflación anual (gastos fijos) | B31: 0.045
A32: ISR (México) | B32: 0.3
A33: Sueldos de fundadores (100%, anual) | B33: 600000
A34: Otros costos fijos año 1 (100%, anual) | B34: 180000
A36: Factor de reducción de sueldos por año (1=100%, 0.5=recorte 50%)
A37: Año | B37: Factor
A38: 1 | B38: 0.5
A39: 2 | B39: 0.5
A40: 3 | B40: 1
A41: 4 | B41: 1
A42: 5 | B42: 1
A43: 6 | B43: 1
A44: 7 | B44: 1
A45: 8 | B45: 1
A47: Nota: años 6-8 (columnas S-T-U) son una extrapolación de la Tabla 26 al mismo ritmo de crecimiento del último tramo documentado (+50% anual) — no están en el reporte, se muestran para responder "¿en cuántos años es viable AeroGuardia?".

Sheet Flujo de efectivo
A1: FLUJO DE EFECTIVO — AeroGuardia
A3: Ventas | C3: ='Estado de Resultados'!N6 -> 285000 | D3: ='Estado de Resultados'!O6 -> 637500 | E3: ='Estado de Resultados'!P6 -> 1068000 | F3: ='Estado de Resultados'!Q6 -> 1605000 | G3: ='Estado de Resultados'!R6 -> 2407500 | H3: ='Estado de Resultados'!S6 -> 3637500 | I3: ='Estado de Resultados'!T6 -> 5457000 | J3: ='Estado de Resultados'!U6 -> 8185500
A5: CONCEPTO | B5: Año 0 | C5: Total año 1 | D5: Total año 2 | E5: Total año 3 | F5: Total año 4 | G5: Total año 5 | H5: Total año 6 | I5: Total año 7 | J5: Total año 8
A6: Saldo inicial de la cuenta en efectivo (informativo, acumulado) | B6: 0 | C6: =B29 -> 0 | D6: =C29 -> -435455.64 | E6: =D29 -> -174455.64 | F6: =E29 -> -157335.14 | G6: =F29 -> 142453.1 | H6: =G29 -> 555938.68 | I6: =H29 -> 1335514.7 | J6: =I29 -> 2318706
A7: Entradas de operación:
A8: Ventas cobradas al contado | C8: =C3 -> 285000 | D8: =D3 -> 637500 | E8: =E3 -> 1068000 | F8: =F3 -> 1605000 | G8: =G3 -> 2407500 | H8: =H3 -> 3637500 | I8: =I3 -> 5457000 | J8: =J3 -> 8185500
A9: Cuentas x cobrar
A10: Otras entradas
A11: Total de entradas de operación | B11: =SUM(B7:B10) -> 0 | C11: =SUM(C7:C10) -> 285000 | D11: =SUM(D7:D10) -> 637500 | E11: =SUM(E7:E10) -> 1068000 | F11: =SUM(F7:F10) -> 1605000 | G11: =SUM(G7:G10) -> 2407500 | H11: =SUM(H7:H10) -> 3637500 | I11: =SUM(I7:I10) -> 5457000 | J11: =SUM(J7:J10) -> 8185500
A12: Salidas de operación:
A13: Costo de ventas | C13: ='Estado de Resultados'!N7 -> 108500 | D13: ='Estado de Resultados'!O7 -> 178400 | E13: ='Estado de Resultados'!P7 -> 241600 | F13: ='Estado de Resultados'!Q7 -> 332000 | G13: ='Estado de Resultados'!R7 -> 498000 | H13: ='Estado de Resultados'!S7 -> 757600 | I13: ='Estado de Resultados'!T7 -> 1128800 | J13: ='Estado de Resultados'!U7 -> 1693200
A14: Gastos de operación (venta + administración) | C14: ='Estado de Resultados'!N11 -> 480000 | D14: ='Estado de Resultados'!O11 -> 501600 | E14: ='Estado de Resultados'!P11 -> 851779.5 | F14: ='Estado de Resultados'!Q11 -> 890109.58 | G14: ='Estado de Resultados'!R11 -> 930164.51 | H14: ='Estado de Resultados'!S11 -> 972021.91 | I14: ='Estado de Resultados'!T11 -> 1015762.9 | J14: ='Estado de Resultados'!U11 -> 1061472.2
A15: Impuestos (ISR) | C15: ='Estado de Resultados'!N15 -> 0 | D15: ='Estado de Resultados'!O15 -> 0 | E15: ='Estado de Resultados'!P15 -> 0 | F15: ='Estado de Resultados'!Q15 -> 108481.68 | G15: ='Estado de Resultados'!R15 -> 291441.16 | H15: ='Estado de Resultados'!S15 -> 572363.43 | I15: ='Estado de Resultados'!T15 -> 993731.13 | J15: ='Estado de Resultados'!U15 -> 1629248.3
A16: Otras salidas de operación
A17: Total de salidas | B17: =SUM(B13:B16) -> 0 | C17: =SUM(C13:C16) -> 588500 | D17: =SUM(D13:D16) -> 680000 | E17: =SUM(E13:E16) -> 1093379.5 | F17: =SUM(F13:F16) -> 1330591.3 | G17: =SUM(G13:G16) -> 1719605.7 | H17: =SUM(H13:H16) -> 2301985.3 | I17: =SUM(I13:I16) -> 3138294 | J17: =SUM(J13:J16) -> 4383920.6
A18: Flujo de efectivo de operación | B18: =B11-B17 -> 0 | C18: =C11-C17 -> -303500 | D18: =D11-D17 -> -42500 | E18: =E11-E17 -> -25379.5 | F18: =F11-F17 -> 274408.74 | G18: =G11-G17 -> 687894.33 | H18: =H11-H17 -> 1335514.7 | I18: =I11-I17 -> 2318706 | J18: =J11-J17 -> 3801579.4
A19: Entradas financieras y de inversión:
A20: Aportaciones de capital | B20: 0
A21: Préstamo bancario | B21: =Amortización!B4 -> 500000
A22: Otras entradas financieras y de inversión
A23: Total de entradas financieras y de inversión: | B23: =SUM(B20:B22) -> 500000 | C23: =SUM(C20:C22) -> 0 | D23: =SUM(D20:D22) -> 0 | E23: =SUM(E20:E22) -> 0 | F23: =SUM(F20:F22) -> 0 | G23: =SUM(G20:G22) -> 0 | H23: =SUM(H20:H22) -> 0 | I23: =SUM(I20:I22) -> 0 | J23: =SUM(J20:J22) -> 0
A24: Salidas financieras y de inversión:
A25: Compra de bienes de capital (inversión inicial) | B25: ='Inversión inicial'!C26 -> 500000
A26: Pago de préstamo e intereses ($0 desde año 6, crédito liquidado) | C26: =Amortización!J16+Amortización!K16 -> 131955.64 | D26: =Amortización!J17+Amortización!K17 -> 131955.64 | E26: =Amortización!J18+Amortización!K18 -> 131955.64 | F26: =Amortización!J19+Amortización!K19 -> 131955.64 | G26: =Amortización!J20+Amortización!K20 -> 131955.64 | H26: =Amortización!J21+Amortización!K21 -> 0 | I26: =Amortización!J22+Amortización!K22 -> 0 | J26: =Amortización!J23+Amortización!K23 -> 0
A27: Otras salidas financieras y de inversión
A28: Total de salidas financieras y de inversión | B28: =SUM(B25:B27) -> 500000 | C28: =SUM(C25:C27) -> 131955.64 | D28: =SUM(D25:D27) -> 131955.64 | E28: =SUM(E25:E27) -> 131955.64 | F28: =SUM(F25:F27) -> 131955.64 | G28: =SUM(G25:G27) -> 131955.64 | H28: =SUM(H25:H27) -> 0 | I28: =SUM(I25:I27) -> 0 | J28: =SUM(J25:J27) -> 0
A29: Flujo neto de efectivo del período | B29: =B18+B23-B28-B6 -> 0 | C29: =C18+C23-C28 -> -435455.64 | D29: =D18+D23-D28 -> -174455.64 | E29: =E18+E23-E28 -> -157335.14 | F29: =F18+F23-F28 -> 142453.1 | G29: =G18+G23-G28 -> 555938.68 | H29: =H18+H23-H28 -> 1335514.7 | I29: =I18+I23-I28 -> 2318706 | J29: =J18+J23-J28 -> 3801579.4
A30: Saldo final de flujo de efectivo | B30: =B18+B23-B28 -> 0 | C30: =C18+C23-C28 -> -435455.64 | D30: =D18+D23-D28 -> -174455.64 | E30: =E18+E23-E28 -> -157335.14 | F30: =F18+F23-F28 -> 142453.1 | G30: =G18+G23-G28 -> 555938.68

Sheet VAN y TIR
A1: VALOR ACTUAL NETO, TASA INTERNA DE RETORNO, ROI Y HORIZONTE DE VIABILIDAD — AeroGuardia
A3: Inversión Inicial | B3: ='Inversión inicial'!C26 -> 500000
D4: Valor Actual Neto | E4: VAN | G4: Tasa Interna de Retorno | H4: TIR | K4: Recuperación de la inversión
A6: Flujos | D6: Inversión inicial (en negativo) | E6: =B21 -> -500000 | G6: Inversión inicial (en negativo) | H6: =B21 -> -500000 | K6: Año | L6: Flujo neto | M6: Acumulado
A7: F1 | B7: ='Flujo de efectivo'!C29 -> -435455.64 | D7: Flujos | E7: =+B7 -> -435455.64 | G7: Flujos | H7: =+E7 -> -435455.64 | K7: 0 | L7: =B21 -> -500000 | M7: =L7 -> -500000
A8: F2 | B8: ='Flujo de efectivo'!D29 -> -174455.64 | E8: =+B8 -> -174455.64 | H8: =+E8 -> -174455.64 | K8: 1 | L8: =B7 -> -435455.64 | M8: =M7+L8 -> -935455.64
A9: F3 | B9: ='Flujo de efectivo'!E29 -> -157335.14 | E9: =+B9 -> -157335.14 | H9: =+E9 -> -157335.14 | K9: 2 | L9: =B8 -> -174455.64 | M9: =M8+L9 -> -1109911.3
A10: F4 | B10: ='Flujo de efectivo'!F29 -> 142453.1 | E10: =+B10 -> 142453.1 | H10: =+E10 -> 142453.1 | K10: 3 | L10: =B9 -> -157335.14 | M10: =M9+L10 -> -1267246.4
A11: F5 | B11: ='Flujo de efectivo'!G29 -> 555938.68 | E11: =+B11 -> 555938.68 | H11: =+E11 -> 555938.68 | K11: 4 | L11: =B10 -> 142453.1 | M11: =M10+L11 -> -1124793.3
A12: F6 | B12: ='Flujo de efectivo'!H29 -> 1335514.7 | E12: =+B12 -> 1335514.7 | H12: =+E12 -> 1335514.7 | K12: 5 | L12: =B11 -> 555938.68 | M12: =M11+L12 -> -568854.65
A13: F7 | B13: ='Flujo de efectivo'!I29 -> 2318706 | E13: =+B13 -> 2318706 | H13: =+E13 -> 2318706 | K13: 6 | L13: =B12 -> 1335514.7 | M13: =M12+L13 -> 766660.01
A14: F8 | B14: ='Flujo de efectivo'!J29 -> 3801579.4 | E14: =+B14 -> 3801579.4 | H14: =+E14 -> 3801579.4 | K14: 7 | L14: =B13 -> 2318706 | M14: =M13+L14 -> 3085366
A15: F9 | E15: =+B15 -> 0 | H15: =+E15 -> 0 | K15: 8 | L15: =B14 -> 3801579.4 | M15: =M14+L15 -> 6886945.4
A16: F10 | E16: =+B16 -> 0 | H16: =+E16 -> 0
A17: F11 | E17: =+B17 -> 0 | H17: =+E17 -> 0 | K17: Periodo de recuperación simple (sin descuento, años) | M17: =IFERROR(IF(M8>=0,1+((-M7)/L8),IF(M9>=0,2+((-M8)/L9),IF(M10>=0,3+((-M9)/L10),IF(M11>=0,4+((-M10)/L11),IF(M12>=0,5+((-M11)/L12),IF(M13>=0,6+((-M12)/L13),IF(M14>=0,7+((-M13)/L14),IF(M15>=0,8+((-M14)/L15),"No se recupera en el horizonte analizado")))))))),"No se recupera en el horizonte analizado") -> 6.4259441
A18: F12 | E18: =+B18 -> 0 | H18: =+E18 -> 0
A19: n (años proyectados) | B19: 8
A20: k = tasa de descuento (costo de la deuda, 100% financiado) | B20: 0.115 | E20: VAN a 5 años | F20: =NPV(B20,E7:E11)+E6 -> -729612.05 | H20: TIR a 5 años | I20: =IRR(H6:H11) -> -0.14756234
A21: Inversión inicial en negativo | B21: =-B3 -> -500000 | E21: VAN a 8 años | F21: =NPV(B20,E7:E14)+E6 -> 2638994.4 | H21: TIR a 8 años | I21: =IRR(H6:H14) -> 0.35754473
A23: ROI a 8 años (Utilidad acumulada / Inversión inicial) | B23: ='Estado de Resultados'!B18 -> 15.773891
D25: El proyecto a 5 años es: | E25: =IF(F20>0,IF(I20>B20,"VIABLE","NO VIABLE"),"NO VIABLE") -> NO VIABLE
D26: El proyecto a 8 años es: | E26: =IF(F21>0,IF(I21>B20,"VIABLE","NO VIABLE"),"NO VIABLE") -> VIABLE
A28: ¿En cuántos años es viable AeroGuardia? El VAN se vuelve positivo entre los años 6 y 7 (ver F20/F21 y la tabla de VAN por horizonte abajo) — el proyecto NO es viable a 5 años bajo el criterio estándar VAN/TIR, pero SÍ es viable a mediano plazo.
A31: VAN por horizonte (n años)
A32: Año | B32: VAN acumulado a ese horizonte
A33: 1 | B33: =NPV($B$20,$E$7:$E7)+$E$6 -> -890543.18
A34: 2 | B34: =NPV($B$20,$E$7:$E8)+$E$6 -> -1030868.3
A35: 3 | B35: =NPV($B$20,$E$7:$E9)+$E$6 -> -1144369.6
A36: 4 | B36: =NPV($B$20,$E$7:$E10)+$E$6 -> -1052203.3
A37: 5 | B37: =NPV($B$20,$E$7:$E11)+$E$6 -> -729612.05
A38: 6 | B38: =NPV($B$20,$E$7:$E12)+$E$6 -> -34588.6
A39: 7 | B39: =NPV($B$20,$E$7:$E13)+$E$6 -> 1047646.5
A40: 8 | B40: =NPV($B$20,$E$7:$E14)+$E$6 -> 2638994.4

Sheet Amortización
A1: Tabla de amortización del crédito
A2: Entidad financiera: crédito empresarial PYME a 5 años (se liquida al final del año 5)
A4: Importe del préstamo (MXN) | B4: ='Inversión inicial'!D32 -> 500000
A5: Interés anual nominal | B5: 0.115
A6: Plazo (años) | B6: 5
A7: Pagos por año | B7: 12
A8: Número total de pagos | B8: =B6*B7 -> 60
A9: Tasa mensual | B9: =B5/B7 -> 0.0095833333
A10: Pago mensual (PMT) | B10: =-PMT(B9,B8,B4) -> 10996.304
A11: Interés total del crédito | B11: =B10*B8-B4 -> 159778.22
A14: Pago Nº | B14: Año | C14: Saldo inicial | D14: Pago mensual | E14: Capital | F14: Intereses | G14: Saldo final | I14: Resumen anual
A15: 1 | B15: =ROUNDUP(A15/12,0) -> 1 | C15: =$B$4 -> 500000 | D15: =$B$10 -> 10996.304 | E15: =D15-F15 -> 6204.637 | F15: =C15*$B$9 -> 4791.6667 | G15: =C15-E15 -> 493795.36 | I15: Año | J15: Interés del año | K15: Capital del año
A16: 2 | B16: =ROUNDUP(A16/12,0) -> 1 | C16: =G15 -> 493795.36 | D16: =$B$10 -> 10996.304 | E16: =D16-F16 -> 6264.0981 | F16: =C16*$B$9 -> 4732.2056 | G16: =C16-E16 -> 487531.26 | I16: 1 | J16: =SUMIF($B$15:$B$74,I16,$F$15:$F$74) -> 53447.458 | K16: =SUMIF($B$15:$B$74,I16,$E$15:$E$74) -> 78508.186
A17: 3 | B17: =ROUNDUP(A17/12,0) -> 1 | C17: =G16 -> 487531.26 | D17: =$B$10 -> 10996.304 | E17: =D17-F17 -> 6324.1291 | F17: =C17*$B$9 -> 4672.1746 | G17: =C17-E17 -> 481207.14 | I17: 2 | J17: =SUMIF($B$15:$B$74,I17,$F$15:$F$74) -> 43927.608 | K17: =SUMIF($B$15:$B$74,I17,$E$15:$E$74) -> 88028.036
A18: 4 | B18: =ROUNDUP(A18/12,0) -> 1 | C18: =G17 -> 481207.14 | D18: =$B$10 -> 10996.304 | E18: =D18-F18 -> 6384.7353 | F18: =C18*$B$9 -> 4611.5684 | G18: =C18-E18 -> 474822.4 | I18: 3 | J18: =SUMIF($B$15:$B$74,I18,$F$15:$F$74) -> 33253.388 | K18: =SUMIF($B$15:$B$74,I18,$E$15:$E$74) -> 98702.256
A19: 5 | B19: =ROUNDUP(A19/12,0) -> 1 | C19: =G18 -> 474822.4 | D19: =$B$10 -> 10996.304 | E19: =D19-F19 -> 6445.9223 | F19: =C19*$B$9 -> 4550.3813 | G19: =C19-E19 -> 468376.48 | I19: 4 | J19: =SUMIF($B$15:$B$74,I19,$F$15:$F$74) -> 21284.818 | K19: =SUMIF($B$15:$B$74,I19,$E$15:$E$74) -> 110670.83
A20: 6 | B20: =ROUNDUP(A20/12,0) -> 1 | C20: =G19 -> 468376.48 | D20: =$B$10 -> 10996.304 | E20: =D20-F20 -> 6507.6958 | F20: =C20*$B$9 -> 4488.6079 | G20: =C20-E20 -> 461868.78 | I20: 5 | J20: =SUMIF($B$15:$B$74,I20,$F$15:$F$74) -> 7864.9485 | K20: =SUMIF($B$15:$B$74,I20,$E$15:$E$74) -> 124090.7
A21: 7 | B21: =ROUNDUP(A21/12,0) -> 1 | C21: =G20 -> 461868.78 | D21: =$B$10 -> 10996.304 | E21: =D21-F21 -> 6570.0612 | F21: =C21*$B$9 -> 4426.2425 | G21: =C21-E21 -> 455298.72 | I21: 6 | J21: =SUMIF($B$15:$B$74,I21,$F$15:$F$74) -> 0 | K21: =SUMIF($B$15:$B$74,I21,$E$15:$E$74) -> 0
A22: 8 | B22: =ROUNDUP(A22/12,0) -> 1 | C22: =G21 -> 455298.72 | D22: =$B$10 -> 10996.304 | E22: =D22-F22 -> 6633.0243 | F22: =C22*$B$9 -> 4363.2794 | G22: =C22-E22 -> 448665.7 | I22: 7 | J22: =SUMIF($B$15:$B$74,I22,$F$15:$F$74) -> 0 | K22: =SUMIF($B$15:$B$74,I22,$E$15:$E$74) -> 0
A23: 9 | B23: =ROUNDUP(A23/12,0) -> 1 | C23: =G22 -> 448665.7 | D23: =$B$10 -> 10996.304 | E23: =D23-F23 -> 6696.5908 | F23: =C23*$B$9 -> 4299.7129 | G23: =C23-E23 -> 441969.11 | I23: 8 | J23: =SUMIF($B$15:$B$74,I23,$F$15:$F$74) -> 0 | K23: =SUMIF($B$15:$B$74,I23,$E$15:$E$74) -> 0
A24: 10 | B24: =ROUNDUP(A24/12,0) -> 1 | C24: =G23 -> 441969.11 | D24: =$B$10 -> 10996.304 | E24: =D24-F24 -> 6760.7664 | F24: =C24*$B$9 -> 4235.5373 | G24: =C24-E24 -> 435208.34
A25: 11 | B25: =ROUNDUP(A25/12,0) -> 1 | C25: =G24 -> 435208.34 | D25: =$B$10 -> 10996.304 | E25: =D25-F25 -> 6825.5571 | F25: =C25*$B$9 -> 4170.7466 | G25: =C25-E25 -> 428382.78
A26: 12 | B26: =ROUNDUP(A26/12,0) -> 1 | C26: =G25 -> 428382.78 | D26: =$B$10 -> 10996.304 | E26: =D26-F26 -> 6890.9687 | F26: =C26*$B$9 -> 4105.335 | G26: =C26-E26 -> 421491.81
A27: 13 | B27: =ROUNDUP(A27/12,0) -> 2 | C27: =G26 -> 421491.81 | D27: =$B$10 -> 10996.304 | E27: =D27-F27 -> 6957.0071 | F27: =C27*$B$9 -> 4039.2966 | G27: =C27-E27 -> 414534.81
A28: 14 | B28: =ROUNDUP(A28/12,0) -> 2 | C28: =G27 -> 414534.81 | D28: =$B$10 -> 10996.304 | E28: =D28-F28 -> 7023.6785 | F28: =C28*$B$9 -> 3972.6252 | G28: =C28-E28 -> 407511.13
A29: 15 | B29: =ROUNDUP(A29/12,0) -> 2 | C29: =G28 -> 407511.13 | D29: =$B$10 -> 10996.304 | E29: =D29-F29 -> 7090.9887 | F29: =C29*$B$9 -> 3905.315 | G29: =C29-E29 -> 400420.14
A30: 16 | B30: =ROUNDUP(A30/12,0) -> 2 | C30: =G29 -> 400420.14 | D30: =$B$10 -> 10996.304 | E30: =D30-F30 -> 7158.944 | F30: =C30*$B$9 -> 3837.3597 | G30: =C30-E30 -> 393261.2
A31: 17 | B31: =ROUNDUP(A31/12,0) -> 2 | C31: =G30 -> 393261.2 | D31: =$B$10 -> 10996.304 | E31: =D31-F31 -> 7227.5506 | F31: =C31*$B$9 -> 3768.7531 | G31: =C31-E31 -> 386033.65
A32: 18 | B32: =ROUNDUP(A32/12,0) -> 2 | C32: =G31 -> 386033.65 | D32: =$B$10 -> 10996.304 | E32: =D32-F32 -> 7296.8146 | F32: =C32*$B$9 -> 3699.4891 | G32: =C32-E32 -> 378736.83
A33: 19 | B33: =ROUNDUP(A33/12,0) -> 2 | C33: =G32 -> 378736.83 | D33: =$B$10 -> 10996.304 | E33: =D33-F33 -> 7366.7424 | F33: =C33*$B$9 -> 3629.5613 | G33: =C33-E33 -> 371370.09
A34: 20 | B34: =ROUNDUP(A34/12,0) -> 2 | C34: =G33 -> 371370.09 | D34: =$B$10 -> 10996.304 | E34: =D34-F34 -> 7437.3403 | F34: =C34*$B$9 -> 3558.9633 | G34: =C34-E34 -> 363932.75
A35: 21 | B35: =ROUNDUP(A35/12,0) -> 2 | C35: =G34 -> 363932.75 | D35: =$B$10 -> 10996.304 | E35: =D35-F35 -> 7508.6149 | F35: =C35*$B$9 -> 3487.6888 | G35: =C35-E35 -> 356424.13
... A74: 60 | B74: =ROUNDUP(A74/12,0) -> 5 | C74: =G73 -> 10891.923 | D74: =$B$10 -> 10996.304 | E74: =D74-F74 -> 10891.923 | F74: =C74*$B$9 -> 104.38093 | G74: =C74-E74 -> 2.2191671e-10
A75: Totales | D75: =SUM(D15:D74) -> 659778.22 | E75: =SUM(E15:E74) -> 500000 | F75: =SUM(F15:F74) -> 159778.22
